Workbook

Sheet Personal de Apoyo
B2: CORPORACION SOCORRISTAS GRUPO DE APOYO | K2: FECHA DE REALIZACION : FR
K3: Atencion Victimas de Violencia Sexual: AVVS
B4: VERIFICACION DEL TALENTO HUMANO | K4: Atencion a Victimas de Ataques con Agentes Quimicos: AVAQ
K5: Reanimacion Cerebro Cardio Pulmonar : BLS
B6: Nº | C6: NOMBRES | D6: APELLIDOS | E6: CONTACTO | F6: NÚMERO DE IDENTIFICACIÓN | G6: REGISTRO | H6: HOJA DE VIDA | I6: RETHUS | J6: ACTA O DIPLOMA | K6: RESOLUCION / TARJETA PROFESIONAL | L6: BLS | P6: AVVS | T6: AVAQ | AB6: CUMPLIMIENTO DOCUMENTO | AC6: DOCUMENTO CERTIFICADO | AD6: TOTAL CUMPLIMIENTO
L9: FR | M9: FV | N9: Dias | O9: Vigente | P9: FR | Q9: FV | R9: Dias | S9: Vigente | T9: FR | U9: FV | V9: Dias | W9: Vigente | X9: CT | Y9: VT | Z9: C | AA9: V
C10: ACTIVOS
C12: =LOOKUP(F12,BD!C:C,BD!A:A) -> ADRIANA | D12: =LOOKUP(F12,BD!C:C,BD!B:B) -> GUERRA QUINTERO | E12: 3024066094 | F12: 1035920680 | G12: =LOOKUP(F12,BD!C:C,BD!D:D) -> 5546622 | H12: OK | I12: OK | J12: OK | K12: OK | L12: 45738 | M12: =L12+730 -> 46468 | N12: =M12-NOW() -> 246.49944 | O12: =IF(N12<=1,"NO CUMPLE",IF(N12>=2,"VIGENTE")) -> VIGENTE | P12: 45751 | Q12: =P12+730 -> 46481 | R12: =Q12-NOW() -> 259.49944 | S12: =IF(R12<=1,"NO CUMPLE",IF(R12>=2,"VIGENTE")) -> VIGENTE | T12: 45749 | U12: =T12+730 -> 46479 | V12: =U12-NOW() -> 257.49944 | W12: =IF(V12<=1,"NO CUMPLE",IF(V12>=2,"VIGENTE")) -> VIGENTE | X12: 4 | Y12: 3 | Z12: =COUNTIF(H12:K12,"OK") -> 4 | AA12: =COUNTIF(L12:W12,"VIGENTE") -> 3 | AB12: =Z12/X12 -> 1 | AC12: =AA12/Y12 -> 1 | AD12: =(Z12+AA12)/7 -> 1
C13: =LOOKUP(F13,BD!C:C,BD!A:A) -> ALEJANDRA | D13: =LOOKUP(F13,BD!C:C,BD!B:B) -> GALLEGO HERNANDEZ | E13: 3126301067 | F13: 1017256315 | G13: =LOOKUP(F13,BD!C:C,BD!D:D) -> 25060172567 | H13: OK | I13: OK | J13: OK | K13: OK | L13: 45597 | M13: =L13+730 -> 46327 | N13: =M13-NOW() -> 105.49944 | O13: =IF(N13<=1,"NO CUMPLE",IF(N13>=2,"VIGENTE")) -> VIGENTE | P13: 45846 | Q13: =P13+365 -> 46211 | R13: =Q13-NOW() -> -10.50056 | S13: =IF(R13<=1,"NO CUMPLE",IF(R13>=2,"VIGENTE")) -> NO CUMPLE | T13: 45846 | U13: =T13+365 -> 46211 | V13: =U13-NOW() -> -10.50056 | W13: =IF(V13<=1,"NO CUMPLE",IF(V13>=2,"VIGENTE")) -> NO CUMPLE | X13: 4 | Y13: 3 | Z13: =COUNTIF(H13:K13,"OK") -> 4 | AA13: =COUNTIF(L13:W13,"VIGENTE") -> 1 | AB13: =Z13/X13 -> 1 | AC13: =AA13/Y13 -> 0.33333333 | AD13: =(Z13+AA13)/7 -> 0.71428571
C14: =LOOKUP(F14,BD!C:C,BD!A:A) -> ANA MARIA | D14: =LOOKUP(F14,BD!C:C,BD!B:B) -> ARENAS CAÑAS | E14: 3225836324 | F14: 1000756090 | G14: =LOOKUP(F14,BD!C:C,BD!D:D) -> 5645223 | H14: OK | I14: OK | J14: OK | K14: OK | L14: 45882 | M14: =L14+730 -> 46612 | N14: =M14-NOW() -> 390.49944 | O14: =IF(N14<=1,"NO CUMPLE",IF(N14>=2,"VIGENTE")) -> VIGENTE | P14: 45882 | Q14: =P14+730 -> 46612 | R14: =Q14-NOW() -> 390.49944 | S14: =IF(R14<=1,"NO CUMPLE",IF(R14>=2,"VIGENTE")) -> VIGENTE | T14: 45882 | U14: =T14+730 -> 46612 | V14: =U14-NOW() -> 390.49944 | W14: =IF(V14<=1,"NO CUMPLE",IF(V14>=2,"VIGENTE")) -> VIGENTE | X14: 4 | Y14: 3 | Z14: =COUNTIF(H14:K14,"OK") -> 4 | AA14: =COUNTIF(L14:W14,"VIGENTE") -> 3 | AB14: =Z14/X14 -> 1 | AC14: =AA14/Y14 -> 1 | AD14: =(Z14+AA14)/7 -> 1
C15: =LOOKUP(F15,BD!C:C,BD!A:A) -> ANA MARIA | D15: =LOOKUP(F15,BD!C:C,BD!B:B) -> PALOMINO RIOS | E15: 3218787093 | F15: 1007240502 | G15: =LOOKUP(F15,BD!C:C,BD!D:D) -> 5454319 | H15: OK | I15: OK | J15: OK | K15: OK | L15: 45541 | M15: =L15+730 -> 46271 | N15: =M15-NOW() -> 49.49944 | O15: =IF(N15<=1,"NO CUMPLE",IF(N15>=2,"VIGENTE")) -> VIGENTE | P15: 45906 | Q15: =P15+365 -> 46271 | R15: =Q15-NOW() -> 49.49944 | S15: =IF(R15<=1,"NO CUMPLE",IF(R15>=2,"VIGENTE")) -> VIGENTE | T15: 45906 | U15: =T15+365 -> 46271 | V15: =U15-NOW() -> 49.49944 | W15: =IF(V15<=1,"NO CUMPLE",IF(V15>=2,"VIGENTE")) -> VIGENTE | X15: 4 | Y15: 3 | Z15: =COUNTIF(H15:K15,"OK") -> 4 | AA15: =COUNTIF(L15:W15,"VIGENTE") -> 3 | AB15: =Z15/X15 -> 1 | AC15: =AA15/Y15 -> 1 | AD15: =(Z15+AA15)/7 -> 1
C16: =LOOKUP(F16,BD!C:C,BD!A:A) -> ANA MARIA | D16: =LOOKUP(F16,BD!C:C,BD!B:B) -> TORRES GOMEZ | E16: 3235038560 | F16: 1036448594 | G16: =LOOKUP(F16,BD!C:C,BD!D:D) -> 25061557315 | H16: OK | I16: OK | J16: OK | K16: OK | L16: 46065 | M16: =L16+365 -> 46430 | N16: =M16-NOW() -> 208.49944 | O16: =IF(N16<=1,"NO CUMPLE",IF(N16>=2,"VIGENTE")) -> VIGENTE | P16: 46067 | Q16: =P16+730 -> 46797 | R16: =Q16-NOW() -> 575.49944 | S16: =IF(R16<=1,"NO CUMPLE",IF(R16>=2,"VIGENTE")) -> VIGENTE | T16: 46066 | U16: =T16+730 -> 46796 | V16: =U16-NOW() -> 574.49944 | W16: =IF(V16<=1,"NO CUMPLE",IF(V16>=2,"VIGENTE")) -> VIGENTE | X16: 4 | Y16: 3 | Z16: =COUNTIF(H16:K16,"OK") -> 4 | AA16: =COUNTIF(L16:W16,"VIGENTE") -> 3 | AB16: =Z16/X16 -> 1 | AC16: =AA16/Y16 -> 1 | AD16: =(Z16+AA16)/7 -> 1
C17: =LOOKUP(F17,BD!C:C,BD!A:A) -> BETSY ALEJANDRA | D17: =LOOKUP(F17,BD!C:C,BD!B:B) -> MONOGA CASTRO | E17: 3153854371 | F17: 1118559091 | G17: =LOOKUP(F17,BD!C:C,BD!D:D) -> 547719 | H17: OK | I17: OK | J17: OK | K17: OK | L17: 46087 | M17: =L17+730 -> 46817 | N17: =M17-NOW() -> 595.49944 | O17: =IF(N17<=1,"NO CUMPLE",IF(N17>=2,"VIGENTE")) -> VIGENTE | P17: 45842 | Q17: =P17+730 -> 46572 | R17: =Q17-NOW() -> 350.49944 | S17: =IF(R17<=1,"NO CUMPLE",IF(R17>=2,"VIGENTE")) -> VIGENTE | T17: 45954 | U17: =T17+365 -> 46319 | V17: =U17-NOW() -> 97.49944 | W17: =IF(V17<=1,"NO CUMPLE",IF(V17>=2,"VIGENTE")) -> VIGENTE | X17: 4 | Y17: 3 | Z17: =COUNTIF(H17:K17,"OK") -> 4 | AA17: =COUNTIF(L17:W17,"VIGENTE") -> 3 | AB17: =Z17/X17 -> 1 | AC17: =AA17/Y17 -> 1 | AD17: =(Z17+AA17)/7 -> 1
C18: =LOOKUP(F18,BD!C:C,BD!A:A) -> CAROLINA | D18: =LOOKUP(F18,BD!C:C,BD!B:B) -> OCAMPO GONZALEZ | E18: 3113816736 | F18: 1000295495 | G18: =LOOKUP(F18,BD!C:C,BD!D:D) -> 5323423 | H18: OK | I18: OK | J18: OK | K18: OK | L18: 46120 | M18: =L18+730 -> 46850 | N18: =M18-NOW() -> 628.49944 | O18: =IF(N18<=1,"NO CUMPLE",IF(N18>=2,"VIGENTE")) -> VIGENTE | P18: 46120 | Q18: =P18+365 -> 46485 | R18: =Q18-NOW() -> 263.49944 | S18: =IF(R18<=1,"NO CUMPLE",IF(R18>=2,"VIGENTE")) -> VIGENTE | T18: 46120 | U18: =T18+365 -> 46485 | V18: =U18-NOW() -> 263.49944 | W18: =IF(V18<=1,"NO CUMPLE",IF(V18>=2,"VIGENTE")) -> VIGENTE | X18: 4 | Y18: 3 | Z18: =COUNTIF(H18:K18,"OK") -> 4 | AA18: =COUNTIF(L18:W18,"VIGENTE") -> 3 | AB18: =Z18/X18 -> 1 | AC18: =AA18/Y18 -> 1 | AD18: =(Z18+AA18)/7 -> 1
C19: =LOOKUP(F19,BD!C:C,BD!A:A) -> CLARA INES | D19: =LOOKUP(F19,BD!C:C,BD!B:B) -> CARDONA ALVAREZ | E19: 3014324032 | F19: 1020400543 | G19: =LOOKUP(F19,BD!C:C,BD!D:D) -> 5353921 | H19: OK | I19: OK | J19: OK | K19: OK | L19: 45880 | M19: =L19+730 -> 46610 | N19: =M19-NOW() -> 388.49944 | O19: =IF(N19<=1,"NO CUMPLE",IF(N19>=2,"VIGENTE")) -> VIGENTE | P19: 45874 | Q19: =P19+365 -> 46239 | R19: =Q19-NOW() -> 17.49944 | S19: =IF(R19<=1,"NO CUMPLE",IF(R19>=2,"VIGENTE")) -> VIGENTE | T19: 45909 | U19: =T19+365 -> 46274 | V19: =U19-NOW() -> 52.49944 | W19: =IF(V19<=1,"NO CUMPLE",IF(V19>=2,"VIGENTE")) -> VIGENTE | X19: 4 | Y19: 3 | Z19: =COUNTIF(H19:K19,"OK") -> 4 | AA19: =COUNTIF(L19:W19,"VIGENTE") -> 3 | AB19: =Z19/X19 -> 1 | AC19: =AA19/Y19 -> 1 | AD19: =(Z19+AA19)/7 -> 1
C20: =LOOKUP(F20,BD!C:C,BD!A:A) -> CLAUDIA XIMENA | D20: =LOOKUP(F20,BD!C:C,BD!B:B) -> CASTAÑO BARRADA | E20: 3186455863 | F20: 1115070893 | G20: =LOOKUP(F20,BD!C:C,BD!D:D) -> 7640032016 | H20: OK | I20: OK | J20: OK | K20: OK | L20: 45873 | M20: =L20+730 -> 46603 | N20: =M20-NOW() -> 381.49944 | O20: =IF(N20<=1,"NO CUMPLE",IF(N20>=2,"VIGENTE")) -> VIGENTE | P20: 45871 | Q20: =P20+365 -> 46236 | R20: =Q20-NOW() -> 14.49944 | S20: =IF(R20<=1,"NO CUMPLE",IF(R20>=2,"VIGENTE")) -> VIGENTE | T20: 45870 | U20: =T20+365 -> 46235 | V20: =U20-NOW() -> 13.49944 | W20: =IF(V20<=1,"NO CUMPLE",IF(V20>=2,"VIGENTE")) -> VIGENTE | X20: 4 | Y20: 3 | Z20: =COUNTIF(H20:K20,"OK") -> 4 | AA20: =COUNTIF(L20:W20,"VIGENTE") -> 3 | AB20: =Z20/X20 -> 1 | AC20: =AA20/Y20 -> 1 | AD20: =(Z20+AA20)/7 -> 1
C21: =LOOKUP(F21,BD!C:C,BD!A:A) -> CRISTIAN FELIPE | D21: =LOOKUP(F21,BD!C:C,BD!B:B) -> ALVAREZ MALDONADO | E21: 3207358413 | F21: 1000204371 | G21: =LOOKUP(F21,BD!C:C,BD!D:D) -> 26060001495 | H21: OK | I21: OK | J21: OK | K21: OK | L21: 45895 | M21: =L21+730 -> 46625 | N21: =M21-NOW() -> 403.49944 | O21: =IF(N21<=1,"NO CUMPLE",IF(N21>=2,"VIGENTE")) -> VIGENTE | P21: 46071 | Q21: =P21+730 -> 46801 | R21: =Q21-NOW() -> 579.49944 | S21: =IF(R21<=1,"NO CUMPLE",IF(R21>=2,"VIGENTE")) -> VIGENTE | T21: 46155 | U21: =T21+730 -> 46885 | V21: =U21-NOW() -> 663.49944 | W21: =IF(V21<=1,"NO CUMPLE",IF(V21>=2,"VIGENTE")) -> VIGENTE | X21: 4 | Y21: 3 | Z21: =COUNTIF(H21:K21,"OK") -> 4 | AA21: =COUNTIF(L21:W21,"VIGENTE") -> 3 | AB21: =Z21/X21 -> 1 | AC21: =AA21/Y21 -> 1 | AD21: =(Z21+AA21)/7 -> 1
C22: =LOOKUP(F22,BD!C:C,BD!A:A) -> DAMARIS | D22: =LOOKUP(F22,BD!C:C,BD!B:B) -> FLOREZ ALVAREZ | E22: 3215552880 | F22: 1128419525 | G22: =LOOKUP(F22,BD!C:C,BD!D:D) -> 5180921 | H22: OK | I22: OK | J22: OK | K22: OK | L22: 45713 | M22: =L22+730 -> 46443 | N22: =M22-NOW() -> 221.49944 | O22: =IF(N22<=1,"NO CUMPLE",IF(N22>=2,"VIGENTE")) -> VIGENTE | P22: 45873 | Q22: =P22+730 -> 46603 | R22: =Q22-NOW() -> 381.49944 | S22: =IF(R22<=1,"NO CUMPLE",IF(R22>=2,"VIGENTE")) -> VIGENTE | T22: 46190 | U22: =T22+365 -> 46555 | V22: =U22-NOW() -> 333.49944 | W22: =IF(V22<=1,"NO CUMPLE",IF(V22>=2,"VIGENTE")) -> VIGENTE | X22: 4 | Y22: 3 | Z22: =COUNTIF(H22:K22,"OK") -> 4 | AA22: =COUNTIF(L22:W22,"VIGENTE") -> 3 | AB22: =Z22/X22 -> 1 | AC22: =AA22/Y22 -> 1 | AD22: =(Z22+AA22)/7 -> 1
C23: =LOOKUP(F23,BD!C:C,BD!A:A) -> DANIELA | D23: =LOOKUP(F23,BD!C:C,BD!B:B) -> ARISTIZABAL FRANCO | E23: 3022736854 | F23: 1035877140 | G23: =LOOKUP(F23,BD!C:C,BD!D:D) -> 5578923 | H23: OK | I23: OK | J23: OK | K23: OK | L23: 46019 | M23: =L23+730 -> 46749 | N23: =M23-NOW() -> 527.49944 | O23: =IF(N23<=1,"NO CUMPLE",IF(N23>=2,"VIGENTE")) -> VIGENTE | P23: 46019 | Q23: =P23+365 -> 46384 | R23: =Q23-NOW() -> 162.49944 | S23: =IF(R23<=1,"NO CUMPLE",IF(R23>=2,"VIGENTE")) -> VIGENTE | T23: 46019 | U23: =T23+365 -> 46384 | V23: =U23-NOW() -> 162.49944 | W23: =IF(V23<=1,"NO CUMPLE",IF(V23>=2,"VIGENTE")) -> VIGENTE | X23: 4 | Y23: 3 | Z23: =COUNTIF(H23:K23,"OK") -> 4 | AA23: =COUNTIF(L23:W23,"VIGENTE") -> 3 | AB23: =Z23/X23 -> 1 | AC23: =AA23/Y23 -> 1 | AD23: =(Z23+AA23)/7 -> 1
C24: =LOOKUP(F24,BD!C:C,BD!A:A) -> DAVID ESTEBAN | D24: =LOOKUP(F24,BD!C:C,BD!B:B) -> GRACIANO DAVID | E24: 3122198227 | F24: 1017130302 | G24: =LOOKUP(F24,BD!C:C,BD!D:D) -> 5025007 | H24: OK | I24: OK | J24: OK | K24: OK | L24: 45771 | M24: =L24+730 -> 46501 | N24: =M24-NOW() -> 279.49944 | O24: =IF(N24<=1,"NO CUMPLE",IF(N24>=2,"VIGENTE")) -> VIGENTE | P24: 46058 | Q24: =P24+365 -> 46423 | R24: =Q24-NOW() -> 201.49944 | S24: =IF(R24<=1,"NO CUMPLE",IF(R24>=2,"VIGENTE")) -> VIGENTE | T24: 46058 | U24: =T24+365 -> 46423 | V24: =U24-NOW() -> 201.49944 | W24: =IF(V24<=1,"NO CUMPLE",IF(V24>=2,"VIGENTE")) -> VIGENTE | X24: 4 | Y24: 3 | Z24: =COUNTIF(H24:K24,"OK") -> 4 | AA24: =COUNTIF(L24:W24,"VIGENTE") -> 3 | AB24: =Z24/X24 -> 1 | AC24: =AA24/Y24 -> 1 | AD24: =(Z24+AA24)/7 -> 1
C25: =LOOKUP(F25,BD!C:C,BD!A:A) -> DAVID MAURICIO | D25: =LOOKUP(F25,BD!C:C,BD!B:B) -> VARGAS ALZATE | E25: 3118326648 | F25: 1017206880 | G25: =LOOKUP(F25,BD!C:C,BD!D:D) -> 5198721 | H25: OK | I25: OK | J25: OK | K25: OK | L25: 46080 | M25: =L25+730 -> 46810 | N25: =M25-NOW() -> 588.49944 | O25: =IF(N25<=1,"NO CUMPLE",IF(N25>=2,"VIGENTE")) -> VIGENTE | P25: 46083 | Q25: =P25+365 -> 46448 | R25: =Q25-NOW() -> 226.49944 | S25: =IF(R25<=1,"NO CUMPLE",IF(R25>=2,"VIGENTE")) -> VIGENTE | T25: 46081 | U25: =T25+365 -> 46446 | V25: =U25-NOW() -> 224.49944 | W25: =IF(V25<=1,"NO CUMPLE",IF(V25>=2,"VIGENTE")) -> VIGENTE | X25: 4 | Y25: 3 | Z25: =COUNTIF(H25:K25,"OK") -> 4 | AA25: =COUNTIF(L25:W25,"VIGENTE") -> 3 | AB25: =Z25/X25 -> 1 | AC25: =AA25/Y25 -> 1 | AD25: =(Z25+AA25)/7 -> 1
C26: =LOOKUP(F26,BD!C:C,BD!A:A) -> DIANA MILENA | D26: =LOOKUP(F26,BD!C:C,BD!B:B) -> ZEA VELASQUEZ | E26: 3023710054 | F26: 43209905 | G26: =LOOKUP(F26,BD!C:C,BD!D:D) -> 5067220 | H26: OK | I26: OK | J26: OK | K26: OK | L26: 46153 | M26: =L26+730 -> 46883 | N26: =M26-NOW() -> 661.49944 | O26: =IF(N26<=1,"NO CUMPLE",IF(N26>=2,"VIGENTE")) -> VIGENTE | P26: 46162 | Q26: =P26+730 -> 46892 | R26: =Q26-NOW() -> 670.49944 | S26: =IF(R26<=1,"NO CUMPLE",IF(R26>=2,"VIGENTE")) -> VIGENTE | T26: 46153 | U26: =T26+730 -> 46883 | V26: =U26-NOW() -> 661.49944 | W26: =IF(V26<=1,"NO CUMPLE",IF(V26>=2,"VIGENTE")) -> VIGENTE | X26: 4 | Y26: 3 | Z26: =COUNTIF(H26:K26,"OK") -> 4 | AA26: =COUNTIF(L26:W26,"VIGENTE") -> 3 | AB26: =Z26/X26 -> 1 | AC26: =AA26/Y26 -> 1 | AD26: =(Z26+AA26)/7 -> 1
C27: =LOOKUP(F27,BD!C:C,BD!A:A) -> DIEGO ALEJANDRO | D27: =LOOKUP(F27,BD!C:C,BD!B:B) -> GUIRALES TANGARIFE | E27: 3013284893 | F27: 1020430557 | G27: =LOOKUP(F27,BD!C:C,BD!D:D) -> 5511823 | H27: OK | I27: OK | J27: OK | K27: OK | L27: 45795 | M27: =L27+730 -> 46525 | N27: =M27-NOW() -> 303.49944 | O27: =IF(N27<=1,"NO CUMPLE",IF(N27>=2,"VIGENTE")) -> VIGENTE | P27: 45795 | Q27: =P27+730 -> 46525 | R27: =Q27-NOW() -> 303.49944 | S27: =IF(R27<=1,"NO CUMPLE",IF(R27>=2,"VIGENTE")) -> VIGENTE | T27: 45795 | U27: =T27+730 -> 46525 | V27: =U27-NOW() -> 303.49944 | W27: =IF(V27<=1,"NO CUMPLE",IF(V27>=2,"VIGENTE")) -> VIGENTE | X27: 4 | Y27: 3 | Z27: =COUNTIF(H27:K27,"OK") -> 4 | AA27: =COUNTIF(L27:W27,"VIGENTE") -> 3 | AB27: =Z27/X27 -> 1 | AC27: =AA27/Y27 -> 1 | AD27: =(Z27+AA27)/7 -> 1
C28: =LOOKUP(F28,BD!C:C,BD!A:A) -> EDWAR MAURICIO | D28: =LOOKUP(F28,BD!C:C,BD!B:B) -> BORJA USUGA | E28: 3184079433 | F28: 1038803821 | G28: =LOOKUP(F28,BD!C:C,BD!D:D) -> 8058 | H28: OK | I28: OK | J28: OK | K28: OK | L28: 45492 | M28: =L28+730 -> 46222 | N28: =M28-NOW() -> 0.49944016 | O28: =IF(N28<=1,"NO CUMPLE",IF(N28>=2,"VIGENTE")) -> NO CUMPLE | P28: 46122 | Q28: =P28+365 -> 46487 | R28: =Q28-NOW() -> 265.49944 | S28: =IF(R28<=1,"NO CUMPLE",IF(R28>=2,"VIGENTE")) -> VIGENTE | T28: 46072 | U28: =T28+365 -> 46437 | V28: =U28-NOW() -> 215.49944 | W28: =IF(V28<=1,"NO CUMPLE",IF(V28>=2,"VIGENTE")) -> VIGENTE | X28: 4 | Y28: 3 | Z28: =COUNTIF(H28:K28,"OK") -> 4 | AA28: =COUNTIF(L28:W28,"VIGENTE") -> 2 | AB28: =Z28/X28 -> 1 | AC28: =AA28/Y28 -> 0.66666667 | AD28: =(Z28+AA28)/7 -> 0.85714286
C29: =LOOKUP(F29,BD!C:C,BD!A:A) -> ELIANA | D29: =LOOKUP(F29,BD!C:C,BD!B:B) -> ZAPATA TORRES | E29: 3015946639 | F29: 1001463828 | G29: =LOOKUP(F29,BD!C:C,BD!D:D) -> 25060005710 | H29: OK | I29: OK | J29: OK | K29: OK | L29: 46022 | M29: =L29+730 -> 46752 | N29: =M29-NOW() -> 530.49944 | O29: =IF(N29<=1,"NO CUMPLE",IF(N29>=2,"VIGENTE")) -> VIGENTE | P29: 45732 | Q29: =P29+730 -> 46462 | R29: =Q29-NOW() -> 240.49944 | S29: =IF(R29<=1,"NO CUMPLE",IF(R29>=2,"VIGENTE")) -> VIGENTE | T29: 45732 | U29: =T29+730 -> 46462 | V29: =U29-NOW() -> 240.49944 | W29: =IF(V29<=1,"NO CUMPLE",IF(V29>=2,"VIGENTE")) -> VIGENTE | X29: 4 | Y29: 3 | Z29: =COUNTIF(H29:K29,"OK") -> 4 | AA29: =COUNTIF(L29:W29,"VIGENTE") -> 3 | AB29: =Z29/X29 -> 1 | AC29: =AA29/Y29 -> 1 | AD29: =(Z29+AA29)/7 -> 1
C30: =LOOKUP(F30,BD!C:C,BD!A:A) -> ELIZABETH | D30: =LOOKUP(F30,BD!C:C,BD!B:B) -> GALEANO GUERRERO | E30: 3107359109 | F30: 1000395063 | G30: =LOOKUP(F30,BD!C:C,BD!D:D) -> 5371218 | H30: OK | I30: OK | J30: OK | K30: OK | L30: 45849 | M30: =L30+730 -> 46579 | N30: =M30-NOW() -> 357.49944 | O30: =IF(N30<=1,"NO CUMPLE",IF(N30>=2,"VIGENTE")) -> VIGENTE | P30: 46017 | Q30: =P30+730 -> 46747 | R30: =Q30-NOW() -> 525.49944 | S30: =IF(R30<=1,"NO CUMPLE",IF(R30>=2,"VIGENTE")) -> VIGENTE | T30: 46043 | U30: =T30+365 -> 46408 | V30: =U30-NOW() -> 186.49944 | W30: =IF(V30<=1,"NO CUMPLE",IF(V30>=2,"VIGENTE")) -> VIGENTE | X30: 4 | Y30: 3 | Z30: =COUNTIF(H30:K30,"OK") -> 4 | AA30: =COUNTIF(L30:W30,"VIGENTE") -> 3 | AB30: =Z30/X30 -> 1 | AC30: =AA30/Y30 -> 1 | AD30: =(Z30+AA30)/7 -> 1
C31: =LOOKUP(F31,BD!C:C,BD!A:A) -> ERIKA YOHANA | D31: =LOOKUP(F31,BD!C:C,BD!B:B) -> MARTINEZ ECHAVARRIA | E31: 3113647180 | F31: 1007387903 | G31: =LOOKUP(F31,BD!C:C,BD!D:D) -> 5185522 | H31: OK | I31: OK | J31: OK | K31: OK | L31: 45467 | M31: =L31+730 -> 46197 | N31: =M31-NOW() -> -24.50056 | O31: =IF(N31<=1,"NO CUMPLE",IF(N31>=2,"VIGENTE")) -> NO CUMPLE | P31: 45811 | Q31: =P31+730 -> 46541 | R31: =Q31-NOW() -> 319.49944 | S31: =IF(R31<=1,"NO CUMPLE",IF(R31>=2,"VIGENTE")) -> VIGENTE | T31: 46135 | U31: =T31+730 -> 46865 | V31: =U31-NOW() -> 643.49944 | W31: =IF(V31<=1,"NO CUMPLE",IF(V31>=2,"VIGENTE")) -> VIGENTE | X31: 4 | Y31: 3 | Z31: =COUNTIF(H31:K31,"OK") -> 4 | AA31: =COUNTIF(L31:W31,"VIGENTE") -> 2 | AB31: =Z31/X31 -> 1 | AC31: =AA31/Y31 -> 0.66666667 | AD31: =(Z31+AA31)/7 -> 0.85714286
C32: =LOOKUP(F32,BD!C:C,BD!A:A) -> FABIANA MERCED | D32: =LOOKUP(F32,BD!C:C,BD!B:B) -> TREJO | E32: 3215949046 | F32: 1007768304 | G32: =LOOKUP(F32,BD!C:C,BD!D:D) -> 5613621 | H32: OK | I32: OK | J32: OK | K32: OK | L32: 45849 | M32: =L32+730 -> 46579 | N32: =M32-NOW() -> 357.49944 | O32: =IF(N32<=1,"NO CUMPLE",IF(N32>=2,"VIGENTE")) -> VIGENTE | P32: 46009 | Q32: =P32+730 -> 46739 | R32: =Q32-NOW() -> 517.49944 | S32: =IF(R32<=1,"NO CUMPLE",IF(R32>=2,"VIGENTE")) -> VIGENTE | T32: 46042 | U32: =T32+365 -> 46407 | V32: =U32-NOW() -> 185.49944 | W32: =IF(V32<=1,"NO CUMPLE",IF(V32>=2,"VIGENTE")) -> VIGENTE | X32: 4 | Y32: 3 | Z32: =COUNTIF(H32:K32,"OK") -> 4 | AA32: =COUNTIF(L32:W32,"VIGENTE") -> 3 | AB32: =Z32/X32 -> 1 | AC32: =AA32/Y32 -> 1 | AD32: =(Z32+AA32)/7 -> 1
C33: =LOOKUP(F33,BD!C:C,BD!A:A) -> GUATAVO LORENZO | D33: =LOOKUP(F33,BD!C:C,BD!B:B) -> CAMARGO SOLANO | E33: 3237569066 | F33: 1124004179 | G33: =LOOKUP(F33,BD!C:C,BD!D:D) -> 590 | H33: OK | I33: OK | J33: OK | K33: OK | L33: 46162 | M33: =L33+730 -> 46892 | N33: =M33-NOW() -> 670.49944 | O33: =IF(N33<=1,"NO CUMPLE",IF(N33>=2,"VIGENTE")) -> VIGENTE | P33: 46162 | Q33: =P33+730 -> 46892 | R33: =Q33-NOW() -> 670.49944 | S33: =IF(R33<=1,"NO CUMPLE",IF(R33>=2,"VIGENTE")) -> VIGENTE | T33: 46162 | U33: =T33+730 -> 46892 | V33: =U33-NOW() -> 670.49944 | W33: =IF(V33<=1,"NO CUMPLE",IF(V33>=2,"VIGENTE")) -> VIGENTE | X33: 4 | Y33: 3 | Z33: =COUNTIF(H33:K33,"OK") -> 4 | AA33: =COUNTIF(L33:W33,"VIGENTE") -> 3 | AB33: =Z33/X33 -> 1 | AC33: =AA33/Y33 -> 1 | AD33: =(Z33+AA33)/7 -> 1
C34: =LOOKUP(F34,BD!C:C,BD!A:A) -> HEIDY VALERIA | D34: =LOOKUP(F34,BD!C:C,BD!B:B) -> GARCES VALENCIA | E34: 3168983212 | F34: 1025881886 | G34: =LOOKUP(F34,BD!C:C,BD!D:D) -> 5439623 | H34: OK | I34: OK | J34: OK | K34: OK | L34: 46005 | M34: =L34+365 -> 46370 | N34: =M34-NOW() -> 148.49944 | O34: =IF(N34<=1,"NO CUMPLE",IF(N34>=2,"VIGENTE")) -> VIGENTE | P34: 46005 | Q34: =P34+365 -> 46370 | R34: =Q34-NOW() -> 148.49944 | S34: =IF(R34<=1,"NO CUMPLE",IF(R34>=2,"VIGENTE")) -> VIGENTE | T34: 46005 | U34: =T34+365 -> 46370 | V34: =U34-NOW() -> 148.49944 | W34: =IF(V34<=1,"NO CUMPLE",IF(V34>=2,"VIGENTE")) -> VIGENTE | X34: 4 | Y34: 3 | Z34: =COUNTIF(H34:K34,"OK") -> 4 | AA34: =COUNTIF(L34:W34,"VIGENTE") -> 3 | AB34: =Z34/X34 -> 1 | AC34: =AA34/Y34 -> 1 | AD34: =(Z34+AA34)/7 -> 1
C35: =LOOKUP(F35,BD!C:C,BD!A:A) -> HELEN VANESSA | D35: =LOOKUP(F35,BD!C:C,BD!B:B) -> VARGAS PEREZ | E35: 3104710721 | F35: 1033655581 | G35: =LOOKUP(F35,BD!C:C,BD!D:D) -> 5250118 | H35: OK | I35: OK | J35: OK | K35: OK | L35: 46190 | M35: =L35+730 -> 46920 | N35: =M35-NOW() -> 698.49944 | O35: =IF(N35<=1,"NO CUMPLE",IF(N35>=2,"VIGENTE")) -> VIGENTE | P35: 46195 | Q35: =P35+730 -> 46925 | R35: =Q35-NOW() -> 703.49944 | S35: =IF(R35<=1,"NO CUMPLE",IF(R35>=2,"VIGENTE")) -> VIGENTE | T35: 46200 | U35: =T35+730 -> 46930 | V35: =U35-NOW() -> 708.49944 | W35: =IF(V35<=1,"NO CUMPLE",IF(V35>=2,"VIGENTE")) -> VIGENTE | X35: 4 | Y35: 3 | Z35: =COUNTIF(H35:K35,"OK") -> 4 | AA35: =COUNTIF(L35:W35,"VIGENTE") -> 3 | AB35: =Z35/X35 -> 1 | AC35: =AA35/Y35 -> 1 | AD35: =(Z35+AA35)/7 -> 1
C36: =LOOKUP(F36,BD!C:C,BD!A:A) -> ISABEL CRISTINA | D36: =LOOKUP(F36,BD!C:C,BD!B:B) -> POSSO BALDOVINO | E36: 3002616386 | F36: 43269224 | G36: =LOOKUP(F36,BD!C:C,BD!D:D) -> 25060180506 | H36: OK | I36: OK | J36: OK | K36: OK | L36: 45874 | M36: =L36+365 -> 46239 | N36: =M36-NOW() -> 17.49944 | O36: =IF(N36<=1,"NO CUMPLE",IF(N36>=2,"VIGENTE")) -> VIGENTE | P36: 45874 | Q36: =P36+365 -> 46239 | R36: =Q36-NOW() -> 17.49944 | S36: =IF(R36<=1,"NO CUMPLE",IF(R36>=2,"VIGENTE")) -> VIGENTE | T36: 45874 | U36: =T36+365 -> 46239 | V36: =U36-NOW() -> 17.49944 | W36: =IF(V36<=1,"NO CUMPLE",IF(V36>=2,"VIGENTE")) -> VIGENTE | X36: 4 | Y36: 3 | Z36: =COUNTIF(H36:K36,"OK") -> 4 | AA36: =COUNTIF(L36:W36,"VIGENTE") -> 3 | AB36: =Z36/X36 -> 1 | AC36: =AA36/Y36 -> 1 | AD36: =(Z36+AA36)/7 -> 1
C37: =LOOKUP(F37,BD!C:C,BD!A:A) -> ISABEL CRISTINA | D37: =LOOKUP(F37,BD!C:C,BD!B:B) -> TABARES CARMONA | E37: 3112325350 | F37: 1015216029 | G37: =LOOKUP(F37,BD!C:C,BD!D:D) -> 5059023 | H37: OK | I37: OK | J37: OK | K37: OK | L37: 46123 | M37: =L37+730 -> 46853 | N37: =M37-NOW() -> 631.49944 | O37: =IF(N37<=1,"NO CUMPLE",IF(N37>=2,"VIGENTE")) -> VIGENTE | P37: 46123 | Q37: =P37+365 -> 46488 | R37: =Q37-NOW() -> 266.49944 | S37: =IF(R37<=1,"NO CUMPLE",IF(R37>=2,"VIGENTE")) -> VIGENTE | T37: 46123 | U37: =T37+365 -> 46488 | V37: =U37-NOW() -> 266.49944 | W37: =IF(V37<=1,"NO CUMPLE",IF(V37>=2,"VIGENTE")) -> VIGENTE | X37: 4 | Y37: 3 | Z37: =COUNTIF(H37:K37,"OK") -> 4 | AA37: =COUNTIF(L37:W37,"VIGENTE") -> 3 | AB37: =Z37/X37 -> 1 | AC37: =AA37/Y37 -> 1 | AD37: =(Z37+AA37)/7 -> 1
C38: =LOOKUP(F38,BD!C:C,BD!A:A) -> JENNIFER VANNESA | D38: =LOOKUP(F38,BD!C:C,BD!B:B) -> MARULANDA ALDANA | E38: 3228912898 | F38: 1017158554 | G38: =LOOKUP(F38,BD!C:C,BD!D:D) -> 24060418981 | H38: OK | I38: OK | J38: OK | K38: OK | L38: 46088 | M38: =L38+730 -> 46818 | N38: =M38-NOW() -> 596.49944 | O38: =IF(N38<=1,"NO CUMPLE",IF(N38>=2,"VIGENTE")) -> VIGENTE | P38: 46122 | Q38: =P38+730 -> 46852 | R38: =Q38-NOW() -> 630.49944 | S38: =IF(R38<=1,"NO CUMPLE",IF(R38>=2,"VIGENTE")) -> VIGENTE | T38: 45636 | U38: =T38+730 -> 46366 | V38: =U38-NOW() -> 144.49944 | W38: =IF(V38<=1,"NO CUMPLE",IF(V38>=2,"VIGENTE")) -> VIGENTE | X38: 4 | Y38: 3 | Z38: =COUNTIF(H38:K38,"OK") -> 4 | AA38: =COUNTIF(L38:W38,"VIGENTE") -> 3 | AB38: =Z38/X38 -> 1 | AC38: =AA38/Y38 -> 1 | AD38: =(Z38+AA38)/7 -> 1
C39: =LOOKUP(F39,BD!C:C,BD!A:A) -> JEYKSON | D39: =LOOKUP(F39,BD!C:C,BD!B:B) -> BETANCUR MARIN | E39: 3214932959 | F39: 98714960 | G39: =LOOKUP(F39,BD!C:C,BD!D:D) -> 25061010963 | H39: OK | I39: OK | J39: OK | K39: OK | L39: 45854 | M39: =L39+730 -> 46584 | N39: =M39-NOW() -> 362.49944 | O39: =IF(N39<=1,"NO CUMPLE",IF(N39>=2,"VIGENTE")) -> VIGENTE | P39: 45854 | Q39: =P39+365 -> 46219 | R39: =Q39-NOW() -> -2.5005598 | S39: =IF(R39<=1,"NO CUMPLE",IF(R39>=2,"VIGENTE")) -> NO CUMPLE | T39: 45933 | U39: =T39+730 -> 46663 | V39: =U39-NOW() -> 441.49944 | W39: =IF(V39<=1,"NO CUMPLE",IF(V39>=2,"VIGENTE")) -> VIGENTE | X39: 4 | Y39: 3 | Z39: =COUNTIF(H39:K39,"OK") -> 4 | AA39: =COUNTIF(L39:W39,"VIGENTE") -> 2 | AB39: =Z39/X39 -> 1 | AC39: =AA39/Y39 -> 0.66666667 | AD39: =(Z39+AA39)/7 -> 0.85714286
C40: =LOOKUP(F40,BD!C:C,BD!A:A) -> JIMENA YULIET | D40: =LOOKUP(F40,BD!C:C,BD!B:B) -> CARTAGENA GARCIA | E40: 3233428385 | F40: 1020453918 | G40: =LOOKUP(F40,BD!C:C,BD!D:D) -> 24060078485 | H40: OK | I40: OK | J40: OK | K40: OK | L40: 45459 | M40: =L40+730 -> 46189 | N40: =M40-NOW() -> -32.50056 | O40: =IF(N40<=1,"NO CUMPLE",IF(N40>=2,"VIGENTE")) -> NO CUMPLE | P40: 45467 | Q40: =P40+730 -> 46197 | R40: =Q40-NOW() -> -24.50056 | S40: =IF(R40<=1,"NO CUMPLE",IF(R40>=2,"VIGENTE")) -> NO CUMPLE | T40: 45463 | U40: =T40+730 -> 46193 | V40: =U40-NOW() -> -28.50056 | W40: =IF(V40<=1,"NO CUMPLE",IF(V40>=2,"VIGENTE")) -> NO CUMPLE | X40: 4 | Y40: 3 | Z40: =COUNTIF(H40:K40,"OK") -> 4 | AA40: =COUNTIF(L40:W40,"VIGENTE") -> 0 | AB40: =Z40/X40 -> 1 | AC40: =AA40/Y40 -> 0 | AD40: =(Z40+AA40)/7 -> 0.57142857
C41: =LOOKUP(F41,BD!C:C,BD!A:A) -> JOHAN SEBASTIAN | D41: =LOOKUP(F41,BD!C:C,BD!B:B) -> LOBO JARAMILLO | E41: 3001268663 | F41: 1193401088 | G41: =LOOKUP(F41,BD!C:C,BD!D:D) -> 3657 | H41: OK | I41: OK | J41: OK | K41: OK | L41: 45996 | M41: =L41+365 -> 46361 | N41: =M41-NOW() -> 139.49944 | O41: =IF(N41<=1,"NO CUMPLE",IF(N41>=2,"VIGENTE")) -> VIGENTE | P41: 45996 | Q41: =P41+365 -> 46361 | R41: =Q41-NOW() -> 139.49944 | S41: =IF(R41<=1,"NO CUMPLE",IF(R41>=2,"VIGENTE")) -> VIGENTE | T41: 45996 | U41: =T41+365 -> 46361 | V41: =U41-NOW() -> 139.49944 | W41: =IF(V41<=1,"NO CUMPLE",IF(V41>=2,"VIGENTE")) -> VIGENTE | X41: 4 | Y41: 3 | Z41: =COUNTIF(H41:K41,"OK") -> 4 | AA41: =COUNTIF(L41:W41,"VIGENTE") -> 3 | AB41: =Z41/X41 -> 1 | AC41: =AA41/Y41 -> 1 | AD41: =(Z41+AA41)/7 -> 1
C42: =LOOKUP(F42,BD!C:C,BD!A:A) -> JOHN ALEJANDRO | D42: =LOOKUP(F42,BD!C:C,BD!B:B) -> GOMEZ GIRALDO | E42: 3126393097 | F42: 1001723999 | G42: =LOOKUP(F42,BD!C:C,BD!D:D) -> 5652022 | H42: OK | I42: OK | J42: OK | K42: OK | L42: 45889 | M42: =L42+730 -> 46619 | N42: =M42-NOW() -> 397.49944 | O42: =IF(N42<=1,"NO CUMPLE",IF(N42>=2,"VIGENTE")) -> VIGENTE | P42: 45889 | Q42: =P42+730 -> 46619 | R42: =Q42-NOW() -> 397.49944 | S42: =IF(R42<=1,"NO CUMPLE",IF(R42>=2,"VIGENTE")) -> VIGENTE | T42: 45889 | U42: =T42+730 -> 46619 | V42: =U42-NOW() -> 397.49944 | W42: =IF(V42<=1,"NO CUMPLE",IF(V42>=2,"VIGENTE")) -> VIGENTE | X42: 4 | Y42: 3 | Z42: =COUNTIF(H42:K42,"OK") -> 4 | AA42: =COUNTIF(L42:W42,"VIGENTE") -> 3 | AB42: =Z42/X42 -> 1 | AC42: =AA42/Y42 -> 1 | AD42: =(Z42+AA42)/7 -> 1
C43: =LOOKUP(F43,BD!C:C,BD!A:A) -> JOHN EDISON | D43: =LOOKUP(F43,BD!C:C,BD!B:B) -> ESPINAL CORREA | E43: 3208600912 | F43: 98712282 | G43: =LOOKUP(F43,BD!C:C,BD!D:D) -> 5221320 | H43: OK | I43: OK | J43: OK | K43: OK | L43: 45553 | M43: =L43+730 -> 46283 | N43: =M43-NOW() -> 61.49944 | O43: =IF(N43<=1,"NO CUMPLE",IF(N43>=2,"VIGENTE")) -> VIGENTE | P43: 45866 | Q43: =P43+730 -> 46596 | R43: =Q43-NOW() -> 374.49944 | S43: =IF(R43<=1,"NO CUMPLE",IF(R43>=2,"VIGENTE")) -> VIGENTE | T43: 45816 | U43: =T43+730 -> 46546 | V43: =U43-NOW() -> 324.49944 | W43: =IF(V43<=1,"NO CUMPLE",IF(V43>=2,"VIGENTE")) -> VIGENTE | X43: 4 | Y43: 3 | Z43: =COUNTIF(H43:K43,"OK") -> 4 | AA43: =COUNTIF(L43:W43,"VIGENTE") -> 3 | AB43: =Z43/X43 -> 1 | AC43: =AA43/Y43 -> 1 | AD43: =(Z43+AA43)/7 -> 1
C44: =LOOKUP(F44,BD!C:C,BD!A:A) -> JOHNNATHAN | D44: =LOOKUP(F44,BD!C:C,BD!B:B) -> GIRALDO PULGARIN | E44: 3205489739 | F44: 1036338137 | G44: =LOOKUP(F44,BD!C:C,BD!D:D) -> 5238820 | H44: OK | I44: OK | J44: OK | K44: OK | L44: 46163 | M44: =L44+730 -> 46893 | N44: =M44-NOW() -> 671.49944 | O44: =IF(N44<=1,"NO CUMPLE",IF(N44>=2,"VIGENTE")) -> VIGENTE | P44: 46162 | Q44: =P44+365 -> 46527 | R44: =Q44-NOW() -> 305.49944 | S44: =IF(R44<=1,"NO CUMPLE",IF(R44>=2,"VIGENTE")) -> VIGENTE | T44: 46161 | U44: =T44+365 -> 46526 | V44: =U44-NOW() -> 304.49944 | W44: =IF(V44<=1,"NO CUMPLE",IF(V44>=2,"VIGENTE")) -> VIGENTE | X44: 4 | Y44: 3 | Z44: =COUNTIF(H44:K44,"OK") -> 4 | AA44: =COUNTIF(L44:W44,"VIGENTE") -> 3 | AB44: =Z44/X44 -> 1 | AC44: =AA44/Y44 -> 1 | AD44: =(Z44+AA44)/7 -> 1
...

Sheet Voluntarios
B2: CORPORACION SOCORRISTAS GRUPO DE APOYO | K2: FECHA DE REALIZACION : FR
K3: Atencion Victimas de Violencia Sexual: AVVS
B4: VERIFICACION DEL TALENTO HUMANO | K4: Atencion a Victimas de Ataques con Agentes Quimicos: AVAQ
K5: Reanimacion Cerebro Cardio Pulmonar : BLS
B6: Nº | C6: NOMBRES | D6: APELLIDOS | E6: CONTACTO | F6: NÚMERO DE IDENTIFICACIÓN | G6: REGISTRO | H6: HOJA DE VIDA | I6: RETHUS | J6: ACTA O DIPLOMA | K6: RESOLUCION / TARJETA PROFESIONAL | L6: BLS | P6: AVVS | T6: AVAQ | AB6: CUMPLIMIENTO DOCUMENTO | AC6: DOCUMENTO CERTIFICADO | AD6: TOTAL CUMPLIMIENTO
L9: FR | M9: FV | N9: Dias | O9: Vigente | P9: FR | Q9: FV | R9: Dias | S9: Vigente | T9: FR | U9: FV | V9: Dias | W9: Vigente | X9: CT | Y9: VT | Z9: C | AA9: V
C11: =LOOKUP(F11,BD!C:C,BD!A:A) -> DIDUAYAN | D11: =LOOKUP(F11,BD!C:C,BD!B:B) -> GOMEZ VASCO | E11: 3136161729 | F11: 1020469042 | G11: =LOOKUP(F11,BD!C:C,BD!D:D) -> 5614013 | H11: OK | I11: OK | J11: OK | K11: OK | L11: 46163 | M11: =L11+730 -> 46893 | N11: =M11-NOW() -> 671.49944 | O11: =IF(N11<=16,"NO CUMPLE",IF(N11>=16,"VIGENTE")) -> VIGENTE | P11: 45743 | Q11: =P11+730 -> 46473 | R11: =Q11-NOW() -> 251.49944 | S11: =IF(R11<=16,"NO CUMPLE",IF(R11>=16,"VIGENTE")) -> VIGENTE | T11: 45744 | U11: =T11+730 -> 46474 | V11: =U11-NOW() -> 252.49944 | W11: =IF(V11<=16,"NO CUMPLE",IF(V11>=16,"VIGENTE")) -> VIGENTE | X11: 4 | Y11: 3 | Z11: =COUNTIF(H11:K11,"OK") -> 4 | AA11: =COUNTIF(L11:W11,"VIGENTE") -> 3 | AB11: =Z11/X11 -> 1 | AC11: =AA11/Y11 -> 1 | AD11: =(Z11+AA11)/7 -> 1
C12: =LOOKUP(F12,BD!C:C,BD!A:A) -> ANDRES FELIPE | D12: =LOOKUP(F12,BD!C:C,BD!B:B) -> GAVIRIA BUSTAMANTE | E12: 3124247466 | F12: 98762700 | G12: =LOOKUP(F12,BD!C:C,BD!D:D) -> 5637517 | H12: OK | I12: OK | J12: OK | K12: OK | L12: 46267 | M12: =L12+730 -> 46997 | N12: =M12-NOW() -> 775.49944 | O12: =IF(N12<=16,"NO CUMPLE",IF(N12>=16,"VIGENTE")) -> VIGENTE | P12: 45408 | Q12: =P12+730 -> 46138 | R12: =Q12-NOW() -> -83.50056 | S12: =IF(R12<=16,"NO CUMPLE",IF(R12>=16,"VIGENTE")) -> NO CUMPLE | T12: 46064 | U12: =T12+730 -> 46794 | V12: =U12-NOW() -> 572.49944 | W12: =IF(V12<=16,"NO CUMPLE",IF(V12>=16,"VIGENTE")) -> VIGENTE | X12: 4 | Y12: 3 | Z12: =COUNTIF(H12:K12,"OK") -> 4 | AA12: =COUNTIF(L12:W12,"VIGENTE") -> 2 | AB12: =Z12/X12 -> 1 | AC12: =AA12/Y12 -> 0.66666667 | AD12: =(Z12+AA12)/7 -> 0.85714286
C13: =LOOKUP(F13,BD!C:C,BD!A:A) -> CATALINA | D13: =LOOKUP(F13,BD!C:C,BD!B:B) -> ORREGO PALACIO | E13: 3122380431 | F13: 1017184709 | G13: =LOOKUP(F13,BD!C:C,BD!D:D) -> 5777516 | H13: OK | I13: OK | J13: OK | K13: OK | M13: =L13+730 -> 730 | N13: =M13-NOW() -> -45491.501 | O13: =IF(N13<=16,"NO CUMPLE",IF(N13>=16,"VIGENTE")) -> NO CUMPLE | Q13: =P13+730 -> 730 | R13: =Q13-NOW() -> -45491.501 | S13: =IF(R13<=16,"NO CUMPLE",IF(R13>=16,"VIGENTE")) -> NO CUMPLE | U13: =T13+730 -> 730 | V13: =U13-NOW() -> -45491.501 | W13: =IF(V13<=16,"NO CUMPLE",IF(V13>=16,"VIGENTE")) -> NO CUMPLE | X13: 4 | Y13: 3 | Z13: =COUNTIF(H13:K13,"OK") -> 4 | AA13: =COUNTIF(L13:W13,"VIGENTE") -> 0 | AB13: =Z13/X13 -> 1 | AC13: =AA13/Y13 -> 0 | AD13: =(Z13+AA13)/7 -> 0.57142857
C14: =LOOKUP(F14,BD!C:C,BD!A:A) -> ROBINSON | D14: =LOOKUP(F14,BD!C:C,BD!B:B) -> SANCHEZ LONDOÑO | E14: 3192128238 | F14: 1214734374 | G14: =LOOKUP(F14,BD!C:C,BD!D:D) -> 5184321 | H14: OK | I14: OK | J14: OK | K14: OK | M14: =L14+730 -> 730 | N14: =M14-NOW() -> -45491.501 | O14: =IF(N14<=16,"NO CUMPLE",IF(N14>=16,"VIGENTE")) -> NO CUMPLE | Q14: =P14+730 -> 730 | R14: =Q14-NOW() -> -45491.501 | S14: =IF(R14<=16,"NO CUMPLE",IF(R14>=16,"VIGENTE")) -> NO CUMPLE | U14: =T14+730 -> 730 | V14: =U14-NOW() -> -45491.501 | W14: =IF(V14<=16,"NO CUMPLE",IF(V14>=16,"VIGENTE")) -> NO CUMPLE | X14: 4 | Y14: 3 | Z14: =COUNTIF(H14:K14,"OK") -> 4 | AA14: =COUNTIF(L14:W14,"VIGENTE") -> 0 | AB14: =Z14/X14 -> 1 | AC14: =AA14/Y14 -> 0 | AD14: =(Z14+AA14)/7 -> 0.57142857
C15: =LOOKUP(F15,BD!C:C,BD!A:A) -> LUIS DANIEL | D15: =LOOKUP(F15,BD!C:C,BD!B:B) -> SERNA SUESCUN | E15: 3137284128 | F15: 1017197109 | G15: =LOOKUP(F15,BD!C:C,BD!D:D) -> 5236518 | I15: OK | L15: 45935 | M15: =L15+730 -> 46665 | N15: =M15-NOW() -> 443.49944 | O15: =IF(N15<=16,"NO CUMPLE",IF(N15>=16,"VIGENTE")) -> VIGENTE | Q15: =P15+730 -> 730 | R15: =Q15-NOW() -> -45491.501 | S15: =IF(R15<=16,"NO CUMPLE",IF(R15>=16,"VIGENTE")) -> NO CUMPLE | T15: 46111 | U15: =T15+730 -> 46841 | V15: =U15-NOW() -> 619.49944 | W15: =IF(V15<=16,"NO CUMPLE",IF(V15>=16,"VIGENTE")) -> VIGENTE | X15: 4 | Y15: 3 | Z15: =COUNTIF(H15:K15,"OK") -> 1 | AA15: =COUNTIF(L15:W15,"VIGENTE") -> 2 | AB15: =Z15/X15 -> 0.25 | AC15: =AA15/Y15 -> 0.66666667 | AD15: =(Z15+AA15)/7 -> 0.42857143
C16: =LOOKUP(F16,BD!C:C,BD!A:A) -> ANDRES MIGUEL | D16: =LOOKUP(F16,BD!C:C,BD!B:B) -> ALMANZA PARRA | F16: 1067961110 | G16: =LOOKUP(F16,BD!C:C,BD!D:D) -> 5442720 | H16: OK | I16: OK | J16: OK | K16: DIPLOBLS | L16: 45438 | M16: =L16+730 -> 46168 | N16: =M16-NOW() -> -53.50056 | O16: =IF(N16<=16,"NO CUMPLE",IF(N16>=16,"VIGENTE")) -> NO CUMPLE | P16: 45951 | Q16: =P16+730 -> 46681 | R16: =Q16-NOW() -> 459.49944 | S16: =IF(R16<=16,"NO CUMPLE",IF(R16>=16,"VIGENTE")) -> VIGENTE | T16: 45953 | U16: =T16+730 -> 46683 | V16: =U16-NOW() -> 461.49944 | W16: =IF(V16<=16,"NO CUMPLE",IF(V16>=16,"VIGENTE")) -> VIGENTE | X16: 4 | Y16: 3 | Z16: =COUNTIF(H16:K16,"OK") -> 3 | AA16: =COUNTIF(L16:W16,"VIGENTE") -> 2 | AB16: =Z16/X16 -> 0.75 | AC16: =AA16/Y16 -> 0.66666667 | AD16: =(Z16+AA16)/7 -> 0.71428571
C17: =LOOKUP(F17,BD!C:C,BD!A:A) -> NEDIS MARIA | D17: =LOOKUP(F17,BD!C:C,BD!B:B) -> SANCHEZ PEREZ | E17: 3229455054 | F17: 30687786 | G17: =LOOKUP(F17,BD!C:C,BD!D:D) -> 2322913 | H17: OK | I17: OK | J17: OK | K17: OK | L17: 45403 | M17: =L17+730 -> 46133 | N17: =M17-NOW() -> -88.50056 | O17: =IF(N17<=16,"NO CUMPLE",IF(N17>=16,"VIGENTE")) -> NO CUMPLE | P17: 45401 | Q17: =P17+730 -> 46131 | R17: =Q17-NOW() -> -90.50056 | S17: =IF(R17<=16,"NO CUMPLE",IF(R17>=16,"VIGENTE")) -> NO CUMPLE | U17: =T17+730 -> 730 | V17: =U17-NOW() -> -45491.501 | W17: =IF(V17<=16,"NO CUMPLE",IF(V17>=16,"VIGENTE")) -> NO CUMPLE | X17: 4 | Y17: 3 | Z17: =COUNTIF(H17:K17,"OK") -> 4 | AA17: =COUNTIF(L17:W17,"VIGENTE") -> 0 | AB17: =Z17/X17 -> 1 | AC17: =AA17/Y17 -> 0 | AD17: =(Z17+AA17)/7 -> 0.57142857
C18: =LOOKUP(F18,BD!C:C,BD!A:A) -> ILSSY ESTEFANIA | D18: =LOOKUP(F18,BD!C:C,BD!B:B) -> GUERRA VALENCIA | E18: 3006395090 | F18: 1128403070 | G18: =LOOKUP(F18,BD!C:C,BD!D:D) -> 5232116 | H18: OK | I18: OK | J18: OK | K18: OK | L18: 46130 | M18: =L18+730 -> 46860 | N18: =M18-NOW() -> 638.49944 | O18: =IF(N18<=16,"NO CUMPLE",IF(N18>=16,"VIGENTE")) -> VIGENTE | Q18: =P18+730 -> 730 | R18: =Q18-NOW() -> -45491.501 | S18: =IF(R18<=16,"NO CUMPLE",IF(R18>=16,"VIGENTE")) -> NO CUMPLE | U18: =T18+730 -> 730 | V18: =U18-NOW() -> -45491.501 | W18: =IF(V18<=16,"NO CUMPLE",IF(V18>=16,"VIGENTE")) -> NO CUMPLE | X18: 4 | Y18: 3 | Z18: =COUNTIF(H18:K18,"OK") -> 4 | AA18: =COUNTIF(L18:W18,"VIGENTE") -> 1 | AB18: =Z18/X18 -> 1 | AC18: =AA18/Y18 -> 0.33333333 | AD18: =(Z18+AA18)/7 -> 0.71428571
C19: =LOOKUP(F19,BD!C:C,BD!A:A) -> SHIRLEY | D19: =LOOKUP(F19,BD!C:C,BD!B:B) -> VIANA VALBUENA | E19: 3234646756 | F19: 1035877000 | G19: =LOOKUP(F19,BD!C:C,BD!D:D) -> 5492616 | H19: OK | I19: OK | J19: OK | K19: OK | M19: =L19+730 -> 730 | N19: =M19-NOW() -> -45491.501 | O19: =IF(N19<=16,"NO CUMPLE",IF(N19>=16,"VIGENTE")) -> NO CUMPLE | Q19: =P19+730 -> 730 | R19: =Q19-NOW() -> -45491.501 | S19: =IF(R19<=16,"NO CUMPLE",IF(R19>=16,"VIGENTE")) -> NO CUMPLE | T19: 46025 | U19: =T19+730 -> 46755 | V19: =U19-NOW() -> 533.49944 | W19: =IF(V19<=16,"NO CUMPLE",IF(V19>=16,"VIGENTE")) -> VIGENTE | X19: 4 | Y19: 3 | Z19: =COUNTIF(H19:K19,"OK") -> 4 | AA19: =COUNTIF(L19:W19,"VIGENTE") -> 1 | AB19: =Z19/X19 -> 1 | AC19: =AA19/Y19 -> 0.33333333 | AD19: =(Z19+AA19)/7 -> 0.71428571
C20: =LOOKUP(F20,BD!C:C,BD!A:A) -> MARIA ISABEL | D20: =LOOKUP(F20,BD!C:C,BD!B:B) -> GALLO TOBON | E20: 3044271368 | F20: 1037641294 | G20: =LOOKUP(F20,BD!C:C,BD!D:D) -> 5547417 | H20: OK | I20: OK | J20: OK | K20: OK | M20: =L20+730 -> 730 | N20: =M20-NOW() -> -45491.501 | O20: =IF(N20<=16,"NO CUMPLE",IF(N20>=16,"VIGENTE")) -> NO CUMPLE | Q20: =P20+730 -> 730 | R20: =Q20-NOW() -> -45491.501 | S20: =IF(R20<=16,"NO CUMPLE",IF(R20>=16,"VIGENTE")) -> NO CUMPLE | U20: =T20+730 -> 730 | V20: =U20-NOW() -> -45491.501 | W20: =IF(V20<=16,"NO CUMPLE",IF(V20>=16,"VIGENTE")) -> NO CUMPLE | X20: 4 | Y20: 3 | Z20: =COUNTIF(H20:K20,"OK") -> 4 | AA20: =COUNTIF(L20:W20,"VIGENTE") -> 0 | AB20: =Z20/X20 -> 1 | AC20: =AA20/Y20 -> 0 | AD20: =(Z20+AA20)/7 -> 0.57142857
C21: =LOOKUP(F21,BD!C:C,BD!A:A) -> JUAN CARLOS | D21: =LOOKUP(F21,BD!C:C,BD!B:B) -> CARO GIL | E21: 3002283930 | F21: 71220062 | G21: =LOOKUP(F21,BD!C:C,BD!D:D) -> 5329322 | H21: OK | I21: OK | J21: OK | K21: OK | L21: 45407 | M21: =L21+730 -> 46137 | N21: =M21-NOW() -> -84.50056 | O21: =IF(N21<=16,"NO CUMPLE",IF(N21>=16,"VIGENTE")) -> NO CUMPLE | P21: 45405 | Q21: =P21+730 -> 46135 | R21: =Q21-NOW() -> -86.50056 | S21: =IF(R21<=16,"NO CUMPLE",IF(R21>=16,"VIGENTE")) -> NO CUMPLE | U21: =T21+730 -> 730 | V21: =U21-NOW() -> -45491.501 | W21: =IF(V21<=16,"NO CUMPLE",IF(V21>=16,"VIGENTE")) -> NO CUMPLE | X21: 4 | Y21: 3 | Z21: =COUNTIF(H21:K21,"OK") -> 4 | AA21: =COUNTIF(L21:W21,"VIGENTE") -> 0 | AB21: =Z21/X21 -> 1 | AC21: =AA21/Y21 -> 0 | AD21: =(Z21+AA21)/7 -> 0.57142857
C22: =LOOKUP(F22,BD!C:C,BD!A:A) -> PALAY | D22: =LOOKUP(F22,BD!C:C,BD!B:B) -> PELAEZ RAMIREZ | E22: 3104156290 | F22: 43606925 | G22: =LOOKUP(F22,BD!C:C,BD!D:D) -> 481 | H22: OK | I22: OK | J22: OK | K22: OK | M22: =L22+730 -> 730 | N22: =M22-NOW() -> -45491.501 | O22: =IF(N22<=16,"NO CUMPLE",IF(N22>=16,"VIGENTE")) -> NO CUMPLE | Q22: =P22+730 -> 730 | R22: =Q22-NOW() -> -45491.501 | S22: =IF(R22<=16,"NO CUMPLE",IF(R22>=16,"VIGENTE")) -> NO CUMPLE | U22: =T22+730 -> 730 | V22: =U22-NOW() -> -45491.501 | W22: =IF(V22<=16,"NO CUMPLE",IF(V22>=16,"VIGENTE")) -> NO CUMPLE | X22: 4 | Y22: 3 | Z22: =COUNTIF(H22:K22,"OK") -> 4 | AA22: =COUNTIF(L22:W22,"VIGENTE") -> 0 | AB22: =Z22/X22 -> 1 | AC22: =AA22/Y22 -> 0 | AD22: =(Z22+AA22)/7 -> 0.57142857
C23: =LOOKUP(F23,BD!C:C,BD!A:A) -> #N/A | D23: =LOOKUP(F23,BD!C:C,BD!B:B) -> #N/A | G23: =LOOKUP(F23,BD!C:C,BD!D:D) -> #N/A | M23: =L23+730 -> 730 | N23: =M23-NOW() -> -45491.501 | O23: =IF(N23<=16,"NO CUMPLE",IF(N23>=16,"VIGENTE")) -> NO CUMPLE | Q23: =P23+730 -> 730 | R23: =Q23-NOW() -> -45491.501 | S23: =IF(R23<=16,"NO CUMPLE",IF(R23>=16,"VIGENTE")) -> NO CUMPLE | U23: =T23+730 -> 730 | V23: =U23-NOW() -> -45491.501 | W23: =IF(V23<=16,"NO CUMPLE",IF(V23>=16,"VIGENTE")) -> NO CUMPLE | X23: 4 | Y23: 3 | Z23: =COUNTIF(H23:K23,"OK") -> 0 | AA23: =COUNTIF(L23:W23,"VIGENTE") -> 0 | AB23: =Z23/X23 -> 0 | AC23: =AA23/Y23 -> 0 | AD23: =(Z23+AA23)/7 -> 0
C24: =LOOKUP(F24,BD!C:C,BD!A:A) -> #N/A | D24: =LOOKUP(F24,BD!C:C,BD!B:B) -> #N/A | G24: =LOOKUP(F24,BD!C:C,BD!D:D) -> #N/A | M24: =L24+730 -> 730 | N24: =M24-NOW() -> -45491.501 | O24: =IF(N24<=16,"NO CUMPLE",IF(N24>=16,"VIGENTE")) -> NO CUMPLE | Q24: =P24+730 -> 730 | R24: =Q24-NOW() -> -45491.501 | S24: =IF(R24<=16,"NO CUMPLE",IF(R24>=16,"VIGENTE")) -> NO CUMPLE | U24: =T24+730 -> 730 | V24: =U24-NOW() -> -45491.501 | W24: =IF(V24<=16,"NO CUMPLE",IF(V24>=16,"VIGENTE")) -> NO CUMPLE | X24: 4 | Y24: 3 | Z24: =COUNTIF(H24:K24,"OK") -> 0 | AA24: =COUNTIF(L24:W24,"VIGENTE") -> 0 | AB24: =Z24/X24 -> 0 | AC24: =AA24/Y24 -> 0 | AD24: =(Z24+AA24)/7 -> 0
C25: =LOOKUP(F25,BD!C:C,BD!A:A) -> #N/A | D25: =LOOKUP(F25,BD!C:C,BD!B:B) -> #N/A | G25: =LOOKUP(F25,BD!C:C,BD!D:D) -> #N/A | M25: =L25+730 -> 730 | N25: =M25-NOW() -> -45491.501 | O25: =IF(N25<=16,"NO CUMPLE",IF(N25>=16,"VIGENTE")) -> NO CUMPLE | Q25: =P25+730 -> 730 | R25: =Q25-NOW() -> -45491.501 | S25: =IF(R25<=16,"NO CUMPLE",IF(R25>=16,"VIGENTE")) -> NO CUMPLE | U25: =T25+730 -> 730 | V25: =U25-NOW() -> -45491.501 | W25: =IF(V25<=16,"NO CUMPLE",IF(V25>=16,"VIGENTE")) -> NO CUMPLE | X25: 4 | Y25: 3 | Z25: =COUNTIF(H25:K25,"OK") -> 0 | AA25: =COUNTIF(L25:W25,"VIGENTE") -> 0 | AB25: =Z25/X25 -> 0 | AC25: =AA25/Y25 -> 0 | AD25: =(Z25+AA25)/7 -> 0
C26: =LOOKUP(F26,BD!C:C,BD!A:A) -> #N/A | D26: =LOOKUP(F26,BD!C:C,BD!B:B) -> #N/A | G26: =LOOKUP(F26,BD!C:C,BD!D:D) -> #N/A | M26: =L26+730 -> 730 | N26: =M26-NOW() -> -45491.501 | O26: =IF(N26<=16,"NO CUMPLE",IF(N26>=16,"VIGENTE")) -> NO CUMPLE | Q26: =P26+730 -> 730 | R26: =Q26-NOW() -> -45491.501 | S26: =IF(R26<=16,"NO CUMPLE",IF(R26>=16,"VIGENTE")) -> NO CUMPLE | U26: =T26+730 -> 730 | V26: =U26-NOW() -> -45491.501 | W26: =IF(V26<=16,"NO CUMPLE",IF(V26>=16,"VIGENTE")) -> NO CUMPLE | X26: 4 | Y26: 3 | Z26: =COUNTIF(H26:K26,"OK") -> 0 | AA26: =COUNTIF(L26:W26,"VIGENTE") -> 0 | AB26: =Z26/X26 -> 0 | AC26: =AA26/Y26 -> 0 | AD26: =(Z26+AA26)/7 -> 0
C27: =LOOKUP(F27,BD!C:C,BD!A:A) -> #N/A | D27: =LOOKUP(F27,BD!C:C,BD!B:B) -> #N/A | G27: =LOOKUP(F27,BD!C:C,BD!D:D) -> #N/A | M27: =L27+730 -> 730 | N27: =M27-NOW() -> -45491.501 | O27: =IF(N27<=16,"NO CUMPLE",IF(N27>=16,"VIGENTE")) -> NO CUMPLE | Q27: =P27+730 -> 730 | R27: =Q27-NOW() -> -45491.501 | S27: =IF(R27<=16,"NO CUMPLE",IF(R27>=16,"VIGENTE")) -> NO CUMPLE | U27: =T27+730 -> 730 | V27: =U27-NOW() -> -45491.501 | W27: =IF(V27<=16,"NO CUMPLE",IF(V27>=16,"VIGENTE")) -> NO CUMPLE | X27: 4 | Y27: 3 | Z27: =COUNTIF(H27:K27,"OK") -> 0 | AA27: =COUNTIF(L27:W27,"VIGENTE") -> 0 | AB27: =Z27/X27 -> 0 | AC27: =AA27/Y27 -> 0 | AD27: =(Z27+AA27)/7 -> 0
C28: =LOOKUP(F28,BD!C:C,BD!A:A) -> #N/A | D28: =LOOKUP(F28,BD!C:C,BD!B:B) -> #N/A | G28: =LOOKUP(F28,BD!C:C,BD!D:D) -> #N/A | M28: =L28+730 -> 730 | N28: =M28-NOW() -> -45491.501 | O28: =IF(N28<=16,"NO CUMPLE",IF(N28>=16,"VIGENTE")) -> NO CUMPLE | Q28: =P28+730 -> 730 | R28: =Q28-NOW() -> -45491.501 | S28: =IF(R28<=16,"NO CUMPLE",IF(R28>=16,"VIGENTE")) -> NO CUMPLE | U28: =T28+730 -> 730 | V28: =U28-NOW() -> -45491.501 | W28: =IF(V28<=16,"NO CUMPLE",IF(V28>=16,"VIGENTE")) -> NO CUMPLE | X28: 4 | Y28: 3 | Z28: =COUNTIF(H28:K28,"OK") -> 0 | AA28: =COUNTIF(L28:W28,"VIGENTE") -> 0 | AB28: =Z28/X28 -> 0 | AC28: =AA28/Y28 -> 0 | AD28: =(Z28+AA28)/7 -> 0
C29: =LOOKUP(F29,BD!C:C,BD!A:A) -> #N/A | D29: =LOOKUP(F29,BD!C:C,BD!B:B) -> #N/A | G29: =LOOKUP(F29,BD!C:C,BD!D:D) -> #N/A | M29: =L29+730 -> 730 | N29: =M29-NOW() -> -45491.501 | O29: =IF(N29<=16,"NO CUMPLE",IF(N29>=16,"VIGENTE")) -> NO CUMPLE | Q29: =P29+730 -> 730 | R29: =Q29-NOW() -> -45491.501 | S29: =IF(R29<=16,"NO CUMPLE",IF(R29>=16,"VIGENTE")) -> NO CUMPLE | U29: =T29+730 -> 730 | V29: =U29-NOW() -> -45491.501 | W29: =IF(V29<=16,"NO CUMPLE",IF(V29>=16,"VIGENTE")) -> NO CUMPLE | X29: 4 | Y29: 3 | Z29: =COUNTIF(H29:K29,"OK") -> 0 | AA29: =COUNTIF(L29:W29,"VIGENTE") -> 0 | AB29: =Z29/X29 -> 0 | AC29: =AA29/Y29 -> 0 | AD29: =(Z29+AA29)/7 -> 0
C30: =LOOKUP(F30,BD!C:C,BD!A:A) -> #N/A | D30: =LOOKUP(F30,BD!C:C,BD!B:B) -> #N/A | G30: =LOOKUP(F30,BD!C:C,BD!D:D) -> #N/A | M30: =L30+730 -> 730 | N30: =M30-NOW() -> -45491.501 | O30: =IF(N30<=16,"NO CUMPLE",IF(N30>=16,"VIGENTE")) -> NO CUMPLE | Q30: =P30+730 -> 730 | R30: =Q30-NOW() -> -45491.501 | S30: =IF(R30<=16,"NO CUMPLE",IF(R30>=16,"VIGENTE")) -> NO CUMPLE | U30: =T30+730 -> 730 | V30: =U30-NOW() -> -45491.501 | W30: =IF(V30<=16,"NO CUMPLE",IF(V30>=16,"VIGENTE")) -> NO CUMPLE | X30: 4 | Y30: 3 | Z30: =COUNTIF(H30:K30,"OK") -> 0 | AA30: =COUNTIF(L30:W30,"VIGENTE") -> 0 | AB30: =Z30/X30 -> 0 | AC30: =AA30/Y30 -> 0 | AD30: =(Z30+AA30)/7 -> 0
C31: =LOOKUP(F31,BD!C:C,BD!A:A) -> #N/A | D31: =LOOKUP(F31,BD!C:C,BD!B:B) -> #N/A | G31: =LOOKUP(F31,BD!C:C,BD!D:D) -> #N/A | M31: =L31+730 -> 730 | N31: =M31-NOW() -> -45491.501 | O31: =IF(N31<=16,"NO CUMPLE",IF(N31>=16,"VIGENTE")) -> NO CUMPLE | Q31: =P31+730 -> 730 | R31: =Q31-NOW() -> -45491.501 | S31: =IF(R31<=16,"NO CUMPLE",IF(R31>=16,"VIGENTE")) -> NO CUMPLE | U31: =T31+730 -> 730 | V31: =U31-NOW() -> -45491.501 | W31: =IF(V31<=16,"NO CUMPLE",IF(V31>=16,"VIGENTE")) -> NO CUMPLE | X31: 4 | Y31: 3 | Z31: =COUNTIF(H31:K31,"OK") -> 0 | AA31: =COUNTIF(L31:W31,"VIGENTE") -> 0 | AB31: =Z31/X31 -> 0 | AC31: =AA31/Y31 -> 0 | AD31: =(Z31+AA31)/7 -> 0
C32: =LOOKUP(F32,BD!C:C,BD!A:A) -> #N/A | D32: =LOOKUP(F32,BD!C:C,BD!B:B) -> #N/A | G32: =LOOKUP(F32,BD!C:C,BD!D:D) -> #N/A | M32: =L32+730 -> 730 | N32: =M32-NOW() -> -45491.501 | O32: =IF(N32<=16,"NO CUMPLE",IF(N32>=16,"VIGENTE")) -> NO CUMPLE | Q32: =P32+730 -> 730 | R32: =Q32-NOW() -> -45491.501 | S32: =IF(R32<=16,"NO CUMPLE",IF(R32>=16,"VIGENTE")) -> NO CUMPLE | U32: =T32+730 -> 730 | V32: =U32-NOW() -> -45491.501 | W32: =IF(V32<=16,"NO CUMPLE",IF(V32>=16,"VIGENTE")) -> NO CUMPLE | X32: 4 | Y32: 3 | Z32: =COUNTIF(H32:K32,"OK") -> 0 | AA32: =COUNTIF(L32:W32,"VIGENTE") -> 0 | AB32: =Z32/X32 -> 0 | AC32: =AA32/Y32 -> 0 | AD32: =(Z32+AA32)/7 -> 0
C33: =LOOKUP(F33,BD!C:C,BD!A:A) -> #N/A | D33: =LOOKUP(F33,BD!C:C,BD!B:B) -> #N/A | G33: =LOOKUP(F33,BD!C:C,BD!D:D) -> #N/A | M33: =L33+730 -> 730 | N33: =M33-NOW() -> -45491.501 | O33: =IF(N33<=16,"NO CUMPLE",IF(N33>=16,"VIGENTE")) -> NO CUMPLE | Q33: =P33+730 -> 730 | R33: =Q33-NOW() -> -45491.501 | S33: =IF(R33<=16,"NO CUMPLE",IF(R33>=16,"VIGENTE")) -> NO CUMPLE | U33: =T33+730 -> 730 | V33: =U33-NOW() -> -45491.501 | W33: =IF(V33<=16,"NO CUMPLE",IF(V33>=16,"VIGENTE")) -> NO CUMPLE | X33: 4 | Y33: 3 | Z33: =COUNTIF(H33:K33,"OK") -> 0 | AA33: =COUNTIF(L33:W33,"VIGENTE") -> 0 | AB33: =Z33/X33 -> 0 | AC33: =AA33/Y33 -> 0 | AD33: =(Z33+AA33)/7 -> 0
C34: =LOOKUP(F34,BD!C:C,BD!A:A) -> #N/A | D34: =LOOKUP(F34,BD!C:C,BD!B:B) -> #N/A | G34: =LOOKUP(F34,BD!C:C,BD!D:D) -> #N/A | M34: =L34+730 -> 730 | N34: =M34-NOW() -> -45491.501 | O34: =IF(N34<=16,"NO CUMPLE",IF(N34>=16,"VIGENTE")) -> NO CUMPLE | Q34: =P34+730 -> 730 | R34: =Q34-NOW() -> -45491.501 | S34: =IF(R34<=16,"NO CUMPLE",IF(R34>=16,"VIGENTE")) -> NO CUMPLE | U34: =T34+730 -> 730 | V34: =U34-NOW() -> -45491.501 | W34: =IF(V34<=16,"NO CUMPLE",IF(V34>=16,"VIGENTE")) -> NO CUMPLE | X34: 4 | Y34: 3 | Z34: =COUNTIF(H34:K34,"OK") -> 0 | AA34: =COUNTIF(L34:W34,"VIGENTE") -> 0 | AB34: =Z34/X34 -> 0 | AC34: =AA34/Y34 -> 0 | AD34: =(Z34+AA34)/7 -> 0
... C166: =LOOKUP(F166,BD!C:C,BD!A:A) -> #N/A | D166: =LOOKUP(F166,BD!C:C,BD!B:B) -> #N/A | G166: =LOOKUP(F166,BD!C:C,BD!D:D) -> #N/A | M166: =L166+730 -> 730 | N166: =M166-NOW() -> -45491.501 | O166: =IF(N166<=16,"NO CUMPLE",IF(N166>=16,"VIGENTE")) -> NO CUMPLE | Q166: =P166+730 -> 730 | R166: =Q166-NOW() -> -45491.501 | S166: =IF(R166<=16,"NO CUMPLE",IF(R166>=16,"VIGENTE")) -> NO CUMPLE | U166: =T166+730 -> 730 | V166: =U166-NOW() -> -45491.501 | W166: =IF(V166<=16,"NO CUMPLE",IF(V166>=16,"VIGENTE")) -> NO CUMPLE | X166: 4 | Y166: 3 | Z166: =COUNTIF(H166:K166,"OK") -> 0 | AA166: =COUNTIF(L166:W166,"VIGENTE") -> 0 | AB166: =Z166/X166 -> 0 | AC166: =AA166/Y166 -> 0 | AD166: =(Z166+AA166)/7 -> 0

Sheet BD
A1: NOMBRES | B1: APELLIDOS | C1: NÚMERO DE IDENTIFICACIÓN | D1: REGISTRO
A2: ANDRES FELIPE | B2: OSORIO BUSTAMANTE | C2: 3378920
A3: JOSE MIGUEL | B3: FERNANDEZ LANDAETA | C3: 4675021 | D3: 25060177953
A4: SAMUEL DAVID | B4: CASTILLO CASTELLANOS | C4: 7533411 | D4: 24060018911
A5: LUIS EDUARDO | B5: RUEDA MURILLO | C5: 15490976
A6: IVAN DARIO | B6: VIEIRA PALACIO | C6: 15665121 | D6: -
A7: NEDIS MARIA | B7: SANCHEZ PEREZ | C7: 30687786 | D7: 2322913
A8: LUCIEL | B8: ZAPATA ARBOLEDA | C8: 32183280 | D8: 5053914
A9: NATALIA CAROLINA | B9: MEJÍA | C9: 32258110 | D9: 25060163402
A10: MARIBEL | B10: MARTINEZ MADRIGAL | C10: 37579675 | D10: 6273
A11: ZAYDA JOHANA | B11: RODRIGUEZ DE LUQUE | C11: 39176010 | D11: 5053909
A12: SORANY MARIA | B12: CARDENAS GOMEZ | C12: 43102696 | D12: 4178
A13: MARISOL | B13: JIMENEZ ARIAS | C13: 43155821 | D13: 5341401
A14: GLORIA MILENA | B14: VALENCIA MARIN | C14: 43169356 | D14: 5670611
A15: DIANA MILENA | B15: ZEA VELASQUEZ | C15: 43209905 | D15: 5067220
A16: ISABEL CRISTINA | B16: POSSO BALDOVINO | C16: 43269224 | D16: 25060180506
A17: LINA MARCELA | B17: RESTREPO MONTAÑO | C17: 43272593 | D17: 5639416 | I17: OK
A18: MARIA SALOME | B18: VALENCIA LUNA | C18: 43555911 | D18: - | I18: PENDIENTE
A19: PALAY | B19: PELAEZ RAMIREZ | C19: 43606925 | D19: 481
A20: ANGELA MARIA | B20: OLARTE SEPULVEDA | C20: 43607099 | D20: 360
A21: NANCY CRISTINA | B21: MONSALVE | C21: 43623145 | D21: 60018289
A22: SANDRA EUGENIA | B22: VIEIRA MONTOYA | C22: 43750392 | D22: 5286001
A23: SANDRA MILENA | B23: FERNANDEZ CORTES | C23: 43754698 | D23: 5132202
A24: MARGARITA MARIA | B24: PALACIO BERRIO | C24: 43915171 | D24: 5782922
A25: CAROLINA | B25: SAAVEDRA PEREA | C25: 43921771 | D25: 5698423
A26: LILIANA LINETH | B26: RODRIGUEZ MARTINEZ | C26: 49789412 | D26: 584
A27: ANDREA | B27: FONSECA FLOREZ | C27: 52285356 | D27: 255312
A28: PAOLA | B28: ACEVEDO PABON | C28: 53037574 | D28: 8927
A29: MAYELBE | B29: GOMEZ PIAMONTE | C29: 63492218 | D29: 5702722
A30: JUAN CARLOS | B30: CARO GIL | C30: 71220062 | D30: 5329322
A31: JHON ALEXANDER | B31: TUBERQUIA HENAO | C31: 71221040 | D31: 5313409
A32: JORGE ABAD | B32: MARIN MARIN | C32: 71531476 | D32: -
A33: SAMUEL | B33: DIAZ CAMARGO | C33: 71587271
A34: OSCAR EMILIO | B34: CASTAÑO GOMEZ | C34: 71708637 | D34: COND
A35: JOSE NOLBERTO | B35: GRAJALES CORREA | C35: 71777291 | D35: -
A36: FREDY HERNANDO | B36: ORTEGON BERMUDEZ | C36: 93131001 | D36: 1560
A37: OLMER ANTONIO | B37: TANGARIFE HIGUITA | C37: 98540523 | D37: 5347011
A38: DUBARIEL DE JESUS | B38: SANCHEZ PARRA | C38: 98558130 | D38: -
A39: JOSE ANIBAL | B39: VILLADA MORALES | C39: 98595642 | D39: -
A40: JOHN EDISON | B40: ESPINAL CORREA | C40: 98712282 | D40: 5221320
...
