Workbook

Sheet HOJA 1
A1: Recurso humano dispuesto para la atención prehospitalaria
A4: Evento | C4: Hora inicio PCU | D4: Hora apertura de puertas | E4: Hora Inicio Evento
A5: SUPER CONCIERTO FERIA DE LAS FLORES
A6: Fecha del evento | C6: Hora finalización Evento | D6: Hora finalización PCU | E6: Tipo Evento
A7: 46242
A9: Representante del Grupo de Socorro en el PCU | C9: IVAN DARIO VIEIRA PALACIO
A10: Coordinador del Grupo de Socorro en terreno | C10: DANIEL SERNA SUESCUN
A11: Hora llegada dispositivo APH | D11: Hora retiro dispositivo APH
A12: Cantidad del recurso humano presentado por el grupo de Socorro | D12: Cantidad ambulancias y tipo para evento
A13: Total de asistentes al evento | D13: Total de pacientes atendidos y/o traladados
A15: PUESTO DE PRIMEROS AUXILIOS NORTE
A16: No. | B16: Nombre | C16: Cédula | D16: Perfil | E16: Registro
A17: 1 | B17: =LOOKUP('HOJA 1'!C17,Hoja4!B:B,Hoja4!A:A) -> ANGELIN GAVIRIA VANEGAS | C17: 1000099681 | D17: =LOOKUP(C17,Hoja4!B:B,Hoja4!D:D) -> APH | E17: =LOOKUP('HOJA 1'!C17,Hoja4!B:B,Hoja4!C:C) -> 25060173755
A18: 2 | B18: =LOOKUP('HOJA 1'!C18,Hoja4!B:B,Hoja4!A:A) -> ANDREA ORTIZ PEREZ | C18: 1037662578 | D18: =LOOKUP(C18,Hoja4!B:B,Hoja4!D:D) -> AUXILIAR EN ENFERMERIA | E18: =LOOKUP('HOJA 1'!C18,Hoja4!B:B,Hoja4!C:C) -> 5422227
A19: 3 | B19: =LOOKUP('HOJA 1'!C19,Hoja4!B:B,Hoja4!A:A) -> MARISOL JIMENEZ ARIAS | C19: 43155821 | D19: =LOOKUP(C19,Hoja4!B:B,Hoja4!D:D) -> MEDICO | E19: =LOOKUP('HOJA 1'!C19,Hoja4!B:B,Hoja4!C:C) -> 3414
A20: 4 | B20: =LOOKUP('HOJA 1'!C20,Hoja4!B:B,Hoja4!A:A) -> #N/A | D20: =LOOKUP(C20,Hoja4!B:B,Hoja4!D:D) -> #N/A | E20: =LOOKUP('HOJA 1'!C20,Hoja4!B:B,Hoja4!C:C) -> #N/A
A21: 5 | B21: =LOOKUP('HOJA 1'!C21,Hoja4!B:B,Hoja4!A:A) -> #N/A | D21: =LOOKUP(C21,Hoja4!B:B,Hoja4!D:D) -> #N/A | E21: =LOOKUP('HOJA 1'!C21,Hoja4!B:B,Hoja4!C:C) -> #N/A
A23: PUESTO DE PRIMEROS AUXILIOS SUR
A24: No. | B24: Nombre | C24: Cédula | D24: Perfil | E24: Registro
A25: 1 | B25: =LOOKUP('HOJA 1'!C25,Hoja4!B:B,Hoja4!A:A) -> #N/A | D25: =LOOKUP(C25,Hoja4!B:B,Hoja4!D:D) -> #N/A | E25: =LOOKUP('HOJA 1'!C25,Hoja4!B:B,Hoja4!C:C) -> #N/A
A26: 2 | B26: =LOOKUP('HOJA 1'!C26,Hoja4!B:B,Hoja4!A:A) -> #N/A | D26: =LOOKUP(C26,Hoja4!B:B,Hoja4!D:D) -> #N/A | E26: =LOOKUP('HOJA 1'!C26,Hoja4!B:B,Hoja4!C:C) -> #N/A
A27: 3 | B27: =LOOKUP('HOJA 1'!C27,Hoja4!B:B,Hoja4!A:A) -> #N/A | D27: =LOOKUP(C27,Hoja4!B:B,Hoja4!D:D) -> #N/A | E27: =LOOKUP('HOJA 1'!C27,Hoja4!B:B,Hoja4!C:C) -> #N/A
A28: 4 | B28: =LOOKUP('HOJA 1'!C28,Hoja4!B:B,Hoja4!A:A) -> #N/A | D28: =LOOKUP(C28,Hoja4!B:B,Hoja4!D:D) -> #N/A | E28: =LOOKUP('HOJA 1'!C28,Hoja4!B:B,Hoja4!C:C) -> #N/A
A29: 5 | B29: =LOOKUP('HOJA 1'!C29,Hoja4!B:B,Hoja4!A:A) -> #N/A | D29: =LOOKUP(C29,Hoja4!B:B,Hoja4!D:D) -> #N/A | E29: =LOOKUP('HOJA 1'!C29,Hoja4!B:B,Hoja4!C:C) -> #N/A
A31: PUESTO DE PRIMEROS AUXILIOS ORIENTAL
A32: No. | B32: Nombre | C32: Cédula | D32: Perfil | E32: Registro
A33: 1 | B33: =LOOKUP('HOJA 1'!C33,Hoja4!B:B,Hoja4!A:A) -> MARYORI ALEJANDRA FRANCO RIOS | C33: 1036674174 | D33: =LOOKUP(C33,Hoja4!B:B,Hoja4!D:D) -> AUXILIAR EN ENFERMERIA | E33: =LOOKUP('HOJA 1'!C33,Hoja4!B:B,Hoja4!C:C) -> 5447719
A34: 2 | B34: =LOOKUP('HOJA 1'!C34,Hoja4!B:B,Hoja4!A:A) -> ORIANA MARIA DAVID MARULANDA | C34: 1038334858 | D34: =LOOKUP(C34,Hoja4!B:B,Hoja4!D:D) -> AUXILIAR EN ENFERMERIA | E34: =LOOKUP('HOJA 1'!C34,Hoja4!B:B,Hoja4!C:C) -> 5797015
A35: 3 | B35: =LOOKUP('HOJA 1'!C35,Hoja4!B:B,Hoja4!A:A) -> VALERY CORTES SOSA | C35: 1001228414 | D35: =LOOKUP(C35,Hoja4!B:B,Hoja4!D:D) -> ESTUDIANTE | E35: =LOOKUP('HOJA 1'!C35,Hoja4!B:B,Hoja4!C:C) -> -
A36: 4 | B36: =LOOKUP('HOJA 1'!C36,Hoja4!B:B,Hoja4!A:A) -> #N/A | D36: =LOOKUP(C36,Hoja4!B:B,Hoja4!D:D) -> #N/A | E36: =LOOKUP('HOJA 1'!C36,Hoja4!B:B,Hoja4!C:C) -> #N/A
A37: 5 | B37: =LOOKUP('HOJA 1'!C37,Hoja4!B:B,Hoja4!A:A) -> #N/A | D37: =LOOKUP(C37,Hoja4!B:B,Hoja4!D:D) -> #N/A | E37: =LOOKUP('HOJA 1'!C37,Hoja4!B:B,Hoja4!C:C) -> #N/A
A39: PUESTO DE PRIMEROS AUXILIOS OCCIDENTAL
A40: No. | B40: Nombre | C40: Cédula | D40: Perfil | E40: Registro
A41: 1 | B41: =LOOKUP('HOJA 1'!C41,Hoja4!B:B,Hoja4!A:A) -> MARIA CAMILA SANCHEZ SANCHEZ | C41: 1017273119 | D41: =LOOKUP(C41,Hoja4!B:B,Hoja4!D:D) -> AUXILIAR EN ENFERMERIA | E41: =LOOKUP('HOJA 1'!C41,Hoja4!B:B,Hoja4!C:C) -> 5652818
A42: 2 | B42: =LOOKUP('HOJA 1'!C42,Hoja4!B:B,Hoja4!A:A) -> MARIA ALEJANDRA RINCON LOPEZ | C42: 1004367322 | D42: =LOOKUP(C42,Hoja4!B:B,Hoja4!D:D) -> ESTUDIANTE | E42: =LOOKUP('HOJA 1'!C42,Hoja4!B:B,Hoja4!C:C) -> -
A43: 3 | B43: =LOOKUP('HOJA 1'!C43,Hoja4!B:B,Hoja4!A:A) -> JULIANA CADAVID OSSA | C43: 1017182984 | D43: =LOOKUP(C43,Hoja4!B:B,Hoja4!D:D) -> ESTUDIANTE | E43: =LOOKUP('HOJA 1'!C43,Hoja4!B:B,Hoja4!C:C) -> 0
A44: 4 | B44: =LOOKUP('HOJA 1'!C44,Hoja4!B:B,Hoja4!A:A) -> #N/A | D44: =LOOKUP(C44,Hoja4!B:B,Hoja4!D:D) -> #N/A | E44: =LOOKUP('HOJA 1'!C44,Hoja4!B:B,Hoja4!C:C) -> #N/A
A45: 5 | B45: =LOOKUP('HOJA 1'!C45,Hoja4!B:B,Hoja4!A:A) -> #N/A | D45: =LOOKUP(C45,Hoja4!B:B,Hoja4!D:D) -> #N/A | E45: =LOOKUP('HOJA 1'!C45,Hoja4!B:B,Hoja4!C:C) -> #N/A
A47: EQUIPO DE INTERVENCION - 1 NORTE ALTA
A48: No. | B48: Nombre | C48: Cédula | D48: Perfil | E48: Registro
...

Sheet Hoja4
A1: NOMBRE COMPLETO | B1: NUMERO DE IDENTIFICACION | C1: REGISTRO | D1: PERFIL | N1: PERFILES
A2: ANDRES FELIPE OSORIO BUSTAMANTE | B2: 3378920 | C2: - | D2: ESTUDIANTE | N2: SOCORRISTA
A3: JOSE MIGUEL FERNANDEZ LANDAETA | B3: 4675021 | C3: 25060177953 | D3: AUXILIAR EN ENFERMERIA | N3: AUXILIAR EN ENFERMERIA
A4: LUIS EDUARDO RUEDA MURILLO | B4: 15490976 | C4: - | D4: SOCORRISTA | N4: ESTUDIANTE
A5: IVAN DARIO VIEIRA PALACIO | B5: 15665121 | C5: - | D5: SOCORRISTA | N5: AUXILIAR EN ENFERMERIA / SOCORRISTA
A6: NEDIS MARIA SANCHEZ PEREZ | B6: 30687786 | C6: 23000229 | D6: AUXILIAR EN ENFERMERIA / SOCORRISTA | N6: MEDICO
A7: MARCELA JARAMILLO JARAMILLO | B7: 32108979 | C7: 5431611 | D7: AUXILIAR EN ENFERMERIA | N7: ENFERMERO
A8: ZAYDA JOHANA RODRIGUEZ DE LUQUE | B8: 39176010 | C8: 5053909 | D8: MEDICO | N8: APH
A9: SORANY MARIA CARDENAS GOMEZ | B9: 43102696 | C9: 4178 | D9: AUXILIAR EN ENFERMERIA | N9: APH / SOCORRISTA
A10: MARISOL JIMENEZ ARIAS | B10: 43155821 | C10: 3414 | D10: MEDICO | N10: CONDUCTOR
A11: IVONNE AYDEE DAVID RUIZ | B11: 43269083 | C11: - | D11: ESTUDIANTE
A12: ISABEL CRISTINA POSSO BALDOVINO | B12: 43269224 | C12: 25060180506 | D12: AUXILIAR EN ENFERMERIA
A13: LINA MARCELA RESTREPO MONTAÑO | B13: 43272593 | C13: 5639416 | D13: AUXILIAR EN ENFERMERIA
A14: MARIA SALOME VALENCIA LUNA | B14: 43555911 | C14: - | D14: SOCORRISTA
A15: ANGELA MARIA OLARTE SEPULVEDA | B15: 43607099 | C15: 360 | D15: AUXILIAR EN ENFERMERIA
A16: NANCY CRISTINA MONSALVE | B16: 43623145 | C16: 60018289 | D16: AUXILIAR EN ENFERMERIA
A17: SANDRA EUGENIA VIEIRA MONTOYA | B17: 43750392 | C17: 52860 | D17: MEDICO
A18: SANDRA MILENA FERNANDEZ CORTEZ | B18: 43754698 | C18: 51322 | D18: AUXILIAR EN ENFERMERIA
A19: MARGARITA MARIA PALACIO BERRIO | B19: 43915171 | C19: 5782922 | D19: AUXILIAR EN ENFERMERIA
A20: SONIA INES LOPEZ MORALES | B20: 44004733 | C20: - | D20: ESTUDIANTE
A21: LILIANA LINETH RODRIGUEZ MARTINEZ | B21: 49789412 | C21: 47854 | D21: AUXILIAR EN ENFERMERIA
A22: ANDREA FONSECA FLOREZ | B22: 52285356 | C22: 5312 | D22: AUXILIAR EN ENFERMERIA
A23: MAYELBE GOMEZ PIAMONTE | B23: 63492218 | C23: 5702722 | D23: APH
A24: JUAN CARLOS CARO GIL | B24: 71220062 | C24: 5329322 | D24: APH / SOCORRISTA
A25: JHON ALEXANDER TUBERQUIA HENAO | B25: 71221040 | C25: 71221040 | D25: MEDICO
A26: DIEGO ALEJANDRO GUTIERREZ HERRERA | B26: 71337752 | C26: COND | D26: CONDUCTOR
A27: JORGE ABAD MARIN MARIN | B27: 71531476 | C27: - | D27: SOCORRISTA
A28: SAMUEL DIAZ CAMARGO | B28: 71587271 | C28: - | D28: SOCORRISTA
A29: GIOVAMNNI ALBERTO CALLE PULGARIN | B29: 71631378 | C29: COND | D29: CONDUCTOR
A30: OSCAR EMILIO CASTAÑO GOMEZ | B30: 71708637 | C30: COND | D30: CONDUCTOR
A31: JOSE NOLBERTO GRAJALES CORREA | B31: 71777291 | C31: - | D31: SOCORRISTA
A32: PEDRO IGNACIO RODRIGUEZ RUIZ | B32: 79530545 | C32: COND | D32: CONDUCTOR
A33: FREDY HERNANDO ORTEGON BERMUDEZ | B33: 93131001 | C33: 1560 | D33: AUXILIAR EN ENFERMERIA
A34: YOVANNI GONZALEZ CARVAJAL | B34: 96124264 | C34: COND | D34: CONDUCTOR
A35: OLMER ANTONIO TANGARIFE HIGUITA | B35: 98540523 | C35: 5347011 | D35: AUXILIAR EN ENFERMERIA
A36: DUBARIEL DE JESUS SANCHEZ PARRA | B36: 98558130 | C36: - | D36: SOCORRISTA
A37: JHON JAIRO LONDOÑO ROJO | B37: 98578664 | C37: COND | D37: CONDUCTOR
A38: JOSE ANIBAL VILLADA MORALES | B38: 98595642 | C38: 5451411 | D38: APH / SOCORRISTA
A39: JOHN EDISON ESPINAL CORREA | B39: 98712282 | C39: 5221320 | D39: APH
A40: JEYKSON BETANCUR MARIN | B40: 98714960 | C40: 25061010963 | D40: APH
...
